<sdf version='1.7'>
  <world name='default'>
    <light name='sun' type='directional'>
      <cast_shadows>1</cast_shadows>
      <pose>0 0 10 0 -0 0</pose>
      <diffuse>0.8 0.8 0.8 1</diffuse>
      <specular>0.2 0.2 0.2 1</specular>
      <attenuation>
        <range>1000</range>
        <constant>0.9</constant>
        <linear>0.01</linear>
        <quadratic>0.001</quadratic>
      </attenuation>
      <direction>0.5 0.1 -0.9</direction>
      <spot>
        <inner_angle>0</inner_angle>
        <outer_angle>0</outer_angle>
        <falloff>0</falloff>
      </spot>
    </light>
    <scene>
      <ambient>0.4 0.4 0.4 1</ambient>
      <background>0.7 0.7 0.7 1</background>
      <shadows>1</shadows>
    </scene>
    <physics type='ode'>
      <max_step_size>0.01</max_step_size>
      <real_time_factor>1</real_time_factor>
      <real_time_update_rate>100</real_time_update_rate>
    </physics>
    <model name='ground_plane_0'>
      <static>1</static>
      <link name='link'>
        <collision name='collision'>
          <geometry>
            <plane>
              <normal>0 0 1</normal>
              <size>100 100</size>
            </plane>
          </geometry>
          <surface>
            <friction>
              <ode>
                <mu>100</mu>
                <mu2>50</mu2>
              </ode>
              <torsional>
                <ode/>
              </torsional>
            </friction>
            <bounce/>
            <contact>
              <ode/>
            </contact>
          </surface>
          <max_contacts>10</max_contacts>
        </collision>
        <visual name='visual'>
          <cast_shadows>0</cast_shadows>
          <geometry>
            <plane>
              <normal>0 0 1</normal>
              <size>100 100</size>
            </plane>
          </geometry>
          <material>
            <script>
              <uri>file://media/materials/scripts/gazebo.material</uri>
              <name>Gazebo/Grey</name>
            </script>
          </material>
        </visual>
        <velocity_decay>
          <linear>0</linear>
          <angular>0</angular>
        </velocity_decay>
        <self_collide>0</self_collide>
        <kinematic>0</kinematic>
        <gravity>1</gravity>
        <enable_wind>0</enable_wind>
      </link>
      <pose>0.497681 0 0 0 -0 0</pose>
    </model>
    <state world_name='default'>
      <sim_time>11086 460000000</sim_time>
      <real_time>346 160889028</real_time>
      <wall_time>1665898153 680720698</wall_time>
      <iterations>34481</iterations>
      <model name='aruco_visual_marker_0'>
        <pose>3.04547 0.013641 0.314 0 -1.56905 0</pose>
        <scale>1 1 1</scale>
        <link name='marker'>
          <pose>3.04547 0.013641 0.314 0 -1.56905 0</pose>
          <velocity>0 0 0 0 -0 0</velocity>
          <acceleration>0 0 0 0 -0 0</acceleration>
          <wrench>0 0 0 0 -0 0</wrench>
        </link>
        <link name='marker_pad'>
          <pose>3.04548 0.013641 0.314 0 -1.56905 0</pose>
          <velocity>0 0 0 0 -0 0</velocity>
          <acceleration>0 0 0 0 -0 0</acceleration>
          <wrench>0 0 0 0 -0 0</wrench>
        </link>
      </model>
      <model name='aruco_visual_marker_1'>
        <pose>3 1 0.379959 3.14159 -1.57079 3.14159</pose>
        <scale>1 1 1</scale>
        <link name='marker'>
          <pose>3 1 0.379959 3.14159 -1.57079 3.14159</pose>
          <velocity>0 0 0 0 -0 0</velocity>
          <acceleration>0 0 0 0 -0 0</acceleration>
          <wrench>0 0 0 0 -0 0</wrench>
        </link>
        <link name='marker_pad'>
          <pose>3.00001 1 0.379959 3.14159 -1.57079 3.14159</pose>
          <velocity>0 0 0 0 -0 0</velocity>
          <acceleration>0 0 0 0 -0 0</acceleration>
          <wrench>0 0 0 0 -0 0</wrench>
        </link>
      </model>
      <model name='aruco_visual_marker_2'>
        <pose>3 2 0.314 0 -1.5668 0</pose>
        <scale>1 1 1</scale>
        <link name='marker'>
          <pose>3 2 0.314 0 -1.5668 0</pose>
          <velocity>0 0 0 0 -0 0</velocity>
          <acceleration>0 0 0 0 -0 0</acceleration>
          <wrench>0 0 0 0 -0 0</wrench>
        </link>
        <link name='marker_pad'>
          <pose>3.00001 2 0.314 0 -1.5668 0</pose>
          <velocity>0 0 0 0 -0 0</velocity>
          <acceleration>0 0 0 0 -0 0</acceleration>
          <wrench>0 0 0 0 -0 0</wrench>
        </link>
      </model>
      <model name='aruco_visual_marker_3'>
        <pose>2.9318 3.0081 0.314007 -3.11983 -1.57079 3.14134</pose>
        <scale>1 1 1</scale>
        <link name='marker'>
          <pose>2.9318 3.0081 0.314007 -3.11983 -1.57079 3.14134</pose>
          <velocity>0 0 0 0 -0 0</velocity>
          <acceleration>0 0 0 0 -0 0</acceleration>
          <wrench>0 0 0 0 -0 0</wrench>
        </link>
        <link name='marker_pad'>
          <pose>2.93181 3.0081 0.314007 -3.11983 -1.57079 3.14134</pose>
          <velocity>0 0 0 0 -0 0</velocity>
          <acceleration>0 0 0 0 -0 0</acceleration>
          <wrench>0 0 0 0 -0 0</wrench>
        </link>
      </model>
      <model name='aruco_visual_marker_4'>
        <pose>2.00063 3 0.363163 1.57019 -1.56905 8e-06</pose>
        <scale>1 1 1</scale>
        <link name='marker'>
          <pose>2.00063 3 0.363163 1.57019 -1.56905 8e-06</pose>
          <velocity>0 0 0 0 -0 0</velocity>
          <acceleration>0 0 0 0 -0 0</acceleration>
          <wrench>0 0 0 0 -0 0</wrench>
        </link>
        <link name='marker_pad'>
          <pose>2.00063 3.00001 0.363163 1.57019 -1.56905 8e-06</pose>
          <velocity>0 0 0 0 -0 0</velocity>
          <acceleration>0 0 0 0 -0 0</acceleration>
          <wrench>0 0 0 0 -0 0</wrench>
        </link>
      </model>
      <model name='ground_plane_0'>
        <pose>1 1 0 0 -0 0</pose>
        <scale>1 1 1</scale>
        <link name='link'>
          <pose>1 1 0 0 -0 0</pose>
          <velocity>0 0 0 0 -0 0</velocity>
          <acceleration>0 0 0 0 -0 0</acceleration>
          <wrench>0 0 0 0 -0 0</wrench>
        </link>
      </model>
      <model name='mobile_base'>
        <pose>-0.002559 0.031581 -0.001131 0.00036 -0.007999 0.498038</pose>
        <scale>1 1 1</scale>
        <link name='base_footprint'>
          <pose>-0.002559 0.031581 -0.001131 0.00036 -0.007999 0.498038</pose>
          <velocity>3.9e-05 1.8e-05 1.3e-05 -0.00063 -0.000357 6.3e-05</velocity>
          <acceleration>-0.000115 0.000541 0.000668 -0.047903 -0.024999 0.009935</acceleration>
          <wrench>-0.000565 0.002664 0.003285 0 -0 0</wrench>
        </link>
        <link name='wheel_left_link'>
          <pose>-0.057738 0.132454 0.035068 -1.57054 -0.187839 0.497991</pose>
          <velocity>2e-05 3.7e-05 -7e-05 -0.00063 -0.000357 6.3e-05</velocity>
          <acceleration>-0.003625 -0.004175 0.734819 -0.103934 -0.07945 0.009</acceleration>
          <wrench>-3.6e-05 -4.2e-05 0.007348 0 -0 0</wrench>
        </link>
        <link name='wheel_right_link'>
          <pose>0.052129 -0.069596 0.035058 -1.56983 1.31879 0.498978</pose>
          <velocity>3.3e-05 4.4e-05 9.6e-05 -0.00063 -0.000357 6.3e-05</velocity>
          <acceleration>-0.002577 -0.00345 0.783031 -0.121662 -0.070526 0.010212</acceleration>
          <wrench>-2.6e-05 -3.4e-05 0.00783 0 -0 0</wrench>
        </link>
      </model>
      <light name='sun'>
        <pose>0 0 10 0 -0 0</pose>
      </light>
    </state>
    <gui fullscreen='0'>
      <camera name='user_camera'>
        <pose>-3.34911 -7.12247 4.50731 0 0.26 1.2108</pose>
        <view_controller>orbit</view_controller>
        <projection_type>perspective</projection_type>
      </camera>
    </gui>
    <gravity>0 0 -9.8</gravity>
    <magnetic_field>6e-06 2.3e-05 -4.2e-05</magnetic_field>
    <atmosphere type='adiabatic'/>
    <wind/>
    <spherical_coordinates>
      <surface_model>EARTH_WGS84</surface_model>
      <latitude_deg>0</latitude_deg>
      <longitude_deg>0</longitude_deg>
      <elevation>0</elevation>
      <heading_deg>0</heading_deg>
    </spherical_coordinates>
    <model name='mobile_base'>
      <link name='base_footprint'>
        <inertial>
          <pose>-0.005943 -0.002852 0.137406 0 -0 0</pose>
          <mass>4.9213</mass>
          <inertia>
            <ixx>0.145198</ixx>
            <ixy>-0.00114677</ixy>
            <ixz>0.0136752</ixz>
            <iyy>0.140226</iyy>
            <iyz>0.00225972</iyz>
            <izz>0.0771053</izz>
          </inertia>
        </inertial>
        <collision name='base_footprint_fixed_joint_lump__base_collision'>
          <pose>0 0 0.06969 0 -0 0</pose>
          <geometry>
            <cylinder>
              <length>0.10938</length>
              <radius>0.178</radius>
            </cylinder>
          </geometry>
          <max_contacts>10</max_contacts>
          <surface>
            <contact>
              <ode/>
            </contact>
            <bounce/>
            <friction>
              <torsional>
                <ode/>
              </torsional>
              <ode/>
            </friction>
          </surface>
        </collision>
        <collision name='base_footprint_fixed_joint_lump__camera_link_collision_1'>
          <pose>-0.087 -0.025 0.2972 0 -0 0</pose>
          <geometry>
            <box>
              <size>0.04 0.165 0.03</size>
            </box>
          </geometry>
          <surface>
            <contact>
              <ode/>
            </contact>
            <friction>
              <ode/>
              <torsional>
                <ode/>
              </torsional>
            </friction>
            <bounce/>
          </surface>
          <max_contacts>10</max_contacts>
        </collision>
        <collision name='base_footprint_fixed_joint_lump__caster_back_link_collision_2'>
          <pose>-0.135 0 0.0192 -1.5708 0 0</pose>
          <geometry>
            <cylinder>
              <length>0.0176</length>
              <radius>0.017</radius>
            </cylinder>
          </geometry>
          <surface>
            <contact>
              <ode>
                <kp>1e+06</kp>
                <kd>100</kd>
                <max_vel>1</max_vel>
                <min_depth>0.001</min_depth>
              </ode>
            </contact>
            <friction>
              <ode>
                <mu>0</mu>
                <mu2>0</mu2>
              </ode>
              <torsional>
                <ode/>
              </torsional>
            </friction>
            <bounce/>
          </surface>
          <max_contacts>10</max_contacts>
        </collision>
        <collision name='base_footprint_fixed_joint_lump__caster_front_link_collision_3'>
          <pose>0.115 0 0.0172 -1.5708 0 0</pose>
          <geometry>
            <cylinder>
              <length>0.0176</length>
              <radius>0.017</radius>
            </cylinder>
          </geometry>
          <surface>
            <contact>
              <ode>
                <kp>1e+06</kp>
                <kd>100</kd>
                <max_vel>1</max_vel>
                <min_depth>0.001</min_depth>
              </ode>
            </contact>
            <friction>
              <ode>
                <mu>0</mu>
                <mu2>0</mu2>
              </ode>
              <torsional>
                <ode/>
              </torsional>
            </friction>
            <bounce/>
          </surface>
          <max_contacts>10</max_contacts>
        </collision>
        <collision name='base_footprint_fixed_joint_lump__plate_bottom_link_collision_4'>
          <pose>0 0 0.1408 0 -0 0</pose>
          <geometry>
            <cylinder>
              <length>0.006</length>
              <radius>0.17</radius>
            </cylinder>
          </geometry>
          <max_contacts>10</max_contacts>
          <surface>
            <contact>
              <ode/>
            </contact>
            <bounce/>
            <friction>
              <torsional>
                <ode/>
              </torsional>
              <ode/>
            </friction>
          </surface>
        </collision>
        <collision name='base_footprint_fixed_joint_lump__plate_middle_link_collision_5'>
          <pose>0 0 0.1976 0 -0 0</pose>
          <geometry>
            <mesh>
              <scale>0.001 0.001 0.001</scale>
              <uri>/home/thiago/turtlebot2/src/turtlebot/turtlebot_description/meshes/stacks/hexagons/plate_simple.stl</uri>
            </mesh>
          </geometry>
          <max_contacts>10</max_contacts>
          <surface>
            <contact>
              <ode/>
            </contact>
            <bounce/>
            <friction>
              <torsional>
                <ode/>
              </torsional>
              <ode/>
            </friction>
          </surface>
        </collision>
        <collision name='base_footprint_fixed_joint_lump__plate_top_link_collision_6'>
          <pose>0 0 0.4068 0 -0 0</pose>
          <geometry>
            <mesh>
              <scale>0.001 0.001 0.001</scale>
              <uri>/home/thiago/turtlebot2/src/turtlebot/turtlebot_description/meshes/stacks/hexagons/plate_simple.stl</uri>
            </mesh>
          </geometry>
          <max_contacts>10</max_contacts>
          <surface>
            <contact>
              <ode/>
            </contact>
            <bounce/>
            <friction>
              <torsional>
                <ode/>
              </torsional>
              <ode/>
            </friction>
          </surface>
        </collision>
        <collision name='base_footprint_fixed_joint_lump__pole_bottom_0_link_collision_7'>
          <pose>0.12 0.082 0.113 0 -0 0</pose>
          <geometry>
            <cylinder>
              <length>0.0492</length>
              <radius>0.006</radius>
            </cylinder>
          </geometry>
          <max_contacts>10</max_contacts>
          <surface>
            <contact>
              <ode/>
            </contact>
            <bounce/>
            <friction>
              <torsional>
                <ode/>
              </torsional>
              <ode/>
            </friction>
          </surface>
        </collision>
        <collision name='base_footprint_fixed_joint_lump__pole_bottom_1_link_collision_8'>
          <pose>0.055 0.12 0.113 0 -0 0</pose>
          <geometry>
            <cylinder>
              <length>0.0492</length>
              <radius>0.006</radius>
            </cylinder>
          </geometry>
          <max_contacts>10</max_contacts>
          <surface>
            <contact>
              <ode/>
            </contact>
            <bounce/>
            <friction>
              <torsional>
                <ode/>
              </torsional>
              <ode/>
            </friction>
          </surface>
        </collision>
        <collision name='base_footprint_fixed_joint_lump__pole_bottom_2_link_collision_9'>
          <pose>-0.055 0.12 0.113 0 -0 0</pose>
          <geometry>
            <cylinder>
              <length>0.0492</length>
              <radius>0.006</radius>
            </cylinder>
          </geometry>
          <max_contacts>10</max_contacts>
          <surface>
            <contact>
              <ode/>
            </contact>
            <bounce/>
            <friction>
              <torsional>
                <ode/>
              </torsional>
              <ode/>
            </friction>
          </surface>
        </collision>
        <collision name='base_footprint_fixed_joint_lump__pole_bottom_3_link_collision_10'>
          <pose>0.12 -0.082 0.113 0 -0 0</pose>
          <geometry>
            <cylinder>
              <length>0.0492</length>
              <radius>0.006</radius>
            </cylinder>
          </geometry>
          <max_contacts>10</max_contacts>
          <surface>
            <contact>
              <ode/>
            </contact>
            <bounce/>
            <friction>
              <torsional>
                <ode/>
              </torsional>
              <ode/>
            </friction>
          </surface>
        </collision>
        <collision name='base_footprint_fixed_joint_lump__pole_bottom_4_link_collision_11'>
          <pose>0.055 -0.12 0.113 0 -0 0</pose>
          <geometry>
            <cylinder>
              <length>0.0492</length>
              <radius>0.006</radius>
            </cylinder>
          </geometry>
          <max_contacts>10</max_contacts>
          <surface>
            <contact>
              <ode/>
            </contact>
            <bounce/>
            <friction>
              <torsional>
                <ode/>
              </torsional>
              <ode/>
            </friction>
          </surface>
        </collision>
        <collision name='base_footprint_fixed_joint_lump__pole_bottom_5_link_collision_12'>
          <pose>-0.055 -0.12 0.113 0 -0 0</pose>
          <geometry>
            <cylinder>
              <length>0.0492</length>
              <radius>0.006</radius>
            </cylinder>
          </geometry>
          <max_contacts>10</max_contacts>
          <surface>
            <contact>
              <ode/>
            </contact>
            <bounce/>
            <friction>
              <torsional>
                <ode/>
              </torsional>
              <ode/>
            </friction>
          </surface>
        </collision>
        <collision name='base_footprint_fixed_joint_lump__pole_kinect_0_link_collision_13'>
          <pose>-0.1024 0.098 0.2474 0 -0 0</pose>
          <geometry>
            <cylinder>
              <length>0.0936</length>
              <radius>0.006</radius>
            </cylinder>
          </geometry>
          <max_contacts>10</max_contacts>
          <surface>
            <contact>
              <ode/>
            </contact>
            <bounce/>
            <friction>
              <torsional>
                <ode/>
              </torsional>
              <ode/>
            </friction>
          </surface>
        </collision>
        <collision name='base_footprint_fixed_joint_lump__pole_kinect_1_link_collision_14'>
          <pose>-0.1024 -0.098 0.2474 0 -0 0</pose>
          <geometry>
            <cylinder>
              <length>0.0936</length>
              <radius>0.006</radius>
            </cylinder>
          </geometry>
          <max_contacts>10</max_contacts>
          <surface>
            <contact>
              <ode/>
            </contact>
            <bounce/>
            <friction>
              <torsional>
                <ode/>
              </torsional>
              <ode/>
            </friction>
          </surface>
        </collision>
        <collision name='base_footprint_fixed_joint_lump__pole_middle_0_link_collision_15'>
          <pose>0.0381 0.1505 0.1742 0 -0 0</pose>
          <geometry>
            <cylinder>
              <length>0.0608</length>
              <radius>0.006</radius>
            </cylinder>
          </geometry>
          <max_contacts>10</max_contacts>
          <surface>
            <contact>
              <ode/>
            </contact>
            <bounce/>
            <friction>
              <torsional>
                <ode/>
              </torsional>
              <ode/>
            </friction>
          </surface>
        </collision>
        <collision name='base_footprint_fixed_joint_lump__pole_middle_1_link_collision_16'>
          <pose>0.0381 -0.1505 0.1742 0 -0 0</pose>
          <geometry>
            <cylinder>
              <length>0.0608</length>
              <radius>0.006</radius>
            </cylinder>
          </geometry>
          <max_contacts>10</max_contacts>
          <surface>
            <contact>
              <ode/>
            </contact>
            <bounce/>
            <friction>
              <torsional>
                <ode/>
              </torsional>
              <ode/>
            </friction>
          </surface>
        </collision>
        <collision name='base_footprint_fixed_joint_lump__pole_middle_2_link_collision_17'>
          <pose>-0.0381 0.1505 0.1742 0 -0 0</pose>
          <geometry>
            <cylinder>
              <length>0.0608</length>
              <radius>0.006</radius>
            </cylinder>
          </geometry>
          <max_contacts>10</max_contacts>
          <surface>
            <contact>
              <ode/>
            </contact>
            <bounce/>
            <friction>
              <torsional>
                <ode/>
              </torsional>
              <ode/>
            </friction>
          </surface>
        </collision>
        <collision name='base_footprint_fixed_joint_lump__pole_middle_3_link_collision_18'>
          <pose>-0.0381 -0.1505 0.1742 0 -0 0</pose>
          <geometry>
            <cylinder>
              <length>0.0608</length>
              <radius>0.006</radius>
            </cylinder>
          </geometry>
          <max_contacts>10</max_contacts>
          <surface>
            <contact>
              <ode/>
            </contact>
            <bounce/>
            <friction>
              <torsional>
                <ode/>
              </torsional>
              <ode/>
            </friction>
          </surface>
        </collision>
        <collision name='base_footprint_fixed_joint_lump__pole_top_0_link_collision_19'>
          <pose>0.0381 0.1505 0.3022 0 -0 0</pose>
          <geometry>
            <cylinder>
              <length>0.2032</length>
              <radius>0.006</radius>
            </cylinder>
          </geometry>
          <max_contacts>10</max_contacts>
          <surface>
            <contact>
              <ode/>
            </contact>
            <bounce/>
            <friction>
              <torsional>
                <ode/>
              </torsional>
              <ode/>
            </friction>
          </surface>
        </collision>
        <collision name='base_footprint_fixed_joint_lump__pole_top_1_link_collision_20'>
          <pose>0.0381 -0.1505 0.3022 0 -0 0</pose>
          <geometry>
            <cylinder>
              <length>0.2032</length>
              <radius>0.006</radius>
            </cylinder>
          </geometry>
          <max_contacts>10</max_contacts>
          <surface>
            <contact>
              <ode/>
            </contact>
            <bounce/>
            <friction>
              <torsional>
                <ode/>
              </torsional>
              <ode/>
            </friction>
          </surface>
        </collision>
        <collision name='base_footprint_fixed_joint_lump__pole_top_2_link_collision_21'>
          <pose>-0.0381 0.1505 0.3022 0 -0 0</pose>
          <geometry>
            <cylinder>
              <length>0.2032</length>
              <radius>0.006</radius>
            </cylinder>
          </geometry>
          <max_contacts>10</max_contacts>
          <surface>
            <contact>
              <ode/>
            </contact>
            <bounce/>
            <friction>
              <torsional>
                <ode/>
              </torsional>
              <ode/>
            </friction>
          </surface>
        </collision>
        <collision name='base_footprint_fixed_joint_lump__pole_top_3_link_collision_22'>
          <pose>-0.0381 -0.1505 0.3022 0 -0 0</pose>
          <geometry>
            <cylinder>
              <length>0.2032</length>
              <radius>0.006</radius>
            </cylinder>
          </geometry>
          <max_contacts>10</max_contacts>
          <surface>
            <contact>
              <ode/>
            </contact>
            <bounce/>
            <friction>
              <torsional>
                <ode/>
              </torsional>
              <ode/>
            </friction>
          </surface>
        </collision>
        <visual name='base_footprint_fixed_joint_lump__base_link_visual'>
          <pose>0.001 0 0.06219 0 -0 0</pose>
          <geometry>
            <mesh>
              <scale>1 1 1</scale>
              <uri>/home/thiago/turtlebot2/src/kobuki_description/meshes/main_body.dae</uri>
            </mesh>
          </geometry>
        </visual>
        <visual name='base_footprint_fixed_joint_lump__camera_link_visual_1'>
          <pose>-0.127 -0.005 0.2872 1.5708 -0 1.5708</pose>
          <geometry>
            <mesh>
              <scale>1 1 1</scale>
              <uri>/home/thiago/turtlebot2/src/turtlebot/turtlebot_description/meshes/sensors/astra.dae</uri>
            </mesh>
          </geometry>
        </visual>
        <visual name='base_footprint_fixed_joint_lump__plate_bottom_link_visual_2'>
          <pose>0.02364 0 0.1408 0 -0 0</pose>
          <geometry>
            <mesh>
              <scale>1 1 1</scale>
              <uri>/home/thiago/turtlebot2/src/turtlebot/turtlebot_description/meshes/stacks/hexagons/plate_bottom.dae</uri>
            </mesh>
          </geometry>
        </visual>
        <visual name='base_footprint_fixed_joint_lump__plate_middle_link_visual_3'>
          <pose>-0.01364 0 0.1976 0 -0 0</pose>
          <geometry>
            <mesh>
              <scale>1 1 1</scale>
              <uri>/home/thiago/turtlebot2/src/turtlebot/turtlebot_description/meshes/stacks/hexagons/plate_middle.dae</uri>
            </mesh>
          </geometry>
        </visual>
        <visual name='base_footprint_fixed_joint_lump__plate_top_link_visual_4'>
          <pose>-0.01364 0 0.4068 0 -0 0</pose>
          <geometry>
            <mesh>
              <scale>1 1 1</scale>
              <uri>/home/thiago/turtlebot2/src/turtlebot/turtlebot_description/meshes/stacks/hexagons/plate_top.dae</uri>
            </mesh>
          </geometry>
        </visual>
        <visual name='base_footprint_fixed_joint_lump__pole_bottom_0_link_visual_5'>
          <pose>0.12 0.082 0.113 0 -0 0</pose>
          <geometry>
            <mesh>
              <scale>1 1 1</scale>
              <uri>/home/thiago/turtlebot2/src/turtlebot/turtlebot_description/meshes/stacks/hexagons/pole_bottom.dae</uri>
            </mesh>
          </geometry>
        </visual>
        <visual name='base_footprint_fixed_joint_lump__pole_bottom_1_link_visual_6'>
          <pose>0.055 0.12 0.113 0 -0 0</pose>
          <geometry>
            <mesh>
              <scale>1 1 1</scale>
              <uri>/home/thiago/turtlebot2/src/turtlebot/turtlebot_description/meshes/stacks/hexagons/pole_bottom.dae</uri>
            </mesh>
          </geometry>
        </visual>
        <visual name='base_footprint_fixed_joint_lump__pole_bottom_2_link_visual_7'>
          <pose>-0.055 0.12 0.113 0 -0 0</pose>
          <geometry>
            <mesh>
              <scale>1 1 1</scale>
              <uri>/home/thiago/turtlebot2/src/turtlebot/turtlebot_description/meshes/stacks/hexagons/pole_bottom.dae</uri>
            </mesh>
          </geometry>
        </visual>
        <visual name='base_footprint_fixed_joint_lump__pole_bottom_3_link_visual_8'>
          <pose>0.12 -0.082 0.113 0 -0 0</pose>
          <geometry>
            <mesh>
              <scale>1 1 1</scale>
              <uri>/home/thiago/turtlebot2/src/turtlebot/turtlebot_description/meshes/stacks/hexagons/pole_bottom.dae</uri>
            </mesh>
          </geometry>
        </visual>
        <visual name='base_footprint_fixed_joint_lump__pole_bottom_4_link_visual_9'>
          <pose>0.055 -0.12 0.113 0 -0 0</pose>
          <geometry>
            <mesh>
              <scale>1 1 1</scale>
              <uri>/home/thiago/turtlebot2/src/turtlebot/turtlebot_description/meshes/stacks/hexagons/pole_bottom.dae</uri>
            </mesh>
          </geometry>
        </visual>
        <visual name='base_footprint_fixed_joint_lump__pole_bottom_5_link_visual_10'>
          <pose>-0.055 -0.12 0.113 0 -0 0</pose>
          <geometry>
            <mesh>
              <scale>1 1 1</scale>
              <uri>/home/thiago/turtlebot2/src/turtlebot/turtlebot_description/meshes/stacks/hexagons/pole_bottom.dae</uri>
            </mesh>
          </geometry>
        </visual>
        <visual name='base_footprint_fixed_joint_lump__pole_kinect_0_link_visual_11'>
          <pose>-0.1024 0.098 0.2474 0 -0 0</pose>
          <geometry>
            <mesh>
              <scale>1 1 1</scale>
              <uri>/home/thiago/turtlebot2/src/turtlebot/turtlebot_description/meshes/stacks/hexagons/pole_kinect.dae</uri>
            </mesh>
          </geometry>
        </visual>
        <visual name='base_footprint_fixed_joint_lump__pole_kinect_1_link_visual_12'>
          <pose>-0.1024 -0.098 0.2474 0 -0 0</pose>
          <geometry>
            <mesh>
              <scale>1 1 1</scale>
              <uri>/home/thiago/turtlebot2/src/turtlebot/turtlebot_description/meshes/stacks/hexagons/pole_kinect.dae</uri>
            </mesh>
          </geometry>
        </visual>
        <visual name='base_footprint_fixed_joint_lump__pole_middle_0_link_visual_13'>
          <pose>0.0381 0.1505 0.1742 3.14159 -0 3.14159</pose>
          <geometry>
            <mesh>
              <scale>1 1 1</scale>
              <uri>/home/thiago/turtlebot2/src/turtlebot/turtlebot_description/meshes/stacks/hexagons/pole_middle.dae</uri>
            </mesh>
          </geometry>
        </visual>
        <visual name='base_footprint_fixed_joint_lump__pole_middle_1_link_visual_14'>
          <pose>0.0381 -0.1505 0.1742 3.14159 -0 3.14159</pose>
          <geometry>
            <mesh>
              <scale>1 1 1</scale>
              <uri>/home/thiago/turtlebot2/src/turtlebot/turtlebot_description/meshes/stacks/hexagons/pole_middle.dae</uri>
            </mesh>
          </geometry>
        </visual>
        <visual name='base_footprint_fixed_joint_lump__pole_middle_2_link_visual_15'>
          <pose>-0.0381 0.1505 0.1742 3.14159 -0 3.14159</pose>
          <geometry>
            <mesh>
              <scale>1 1 1</scale>
              <uri>/home/thiago/turtlebot2/src/turtlebot/turtlebot_description/meshes/stacks/hexagons/pole_middle.dae</uri>
            </mesh>
          </geometry>
        </visual>
        <visual name='base_footprint_fixed_joint_lump__pole_middle_3_link_visual_16'>
          <pose>-0.0381 -0.1505 0.1742 3.14159 -0 3.14159</pose>
          <geometry>
            <mesh>
              <scale>1 1 1</scale>
              <uri>/home/thiago/turtlebot2/src/turtlebot/turtlebot_description/meshes/stacks/hexagons/pole_middle.dae</uri>
            </mesh>
          </geometry>
        </visual>
        <visual name='base_footprint_fixed_joint_lump__pole_top_0_link_visual_17'>
          <pose>0.0381 0.1505 0.3022 0 -0 0</pose>
          <geometry>
            <mesh>
              <scale>1 1 1</scale>
              <uri>/home/thiago/turtlebot2/src/turtlebot/turtlebot_description/meshes/stacks/hexagons/pole_top.dae</uri>
            </mesh>
          </geometry>
        </visual>
        <visual name='base_footprint_fixed_joint_lump__pole_top_1_link_visual_18'>
          <pose>0.0381 -0.1505 0.3022 0 -0 0</pose>
          <geometry>
            <mesh>
              <scale>1 1 1</scale>
              <uri>/home/thiago/turtlebot2/src/turtlebot/turtlebot_description/meshes/stacks/hexagons/pole_top.dae</uri>
            </mesh>
          </geometry>
        </visual>
        <visual name='base_footprint_fixed_joint_lump__pole_top_2_link_visual_19'>
          <pose>-0.0381 0.1505 0.3022 0 -0 0</pose>
          <geometry>
            <mesh>
              <scale>1 1 1</scale>
              <uri>/home/thiago/turtlebot2/src/turtlebot/turtlebot_description/meshes/stacks/hexagons/pole_top.dae</uri>
            </mesh>
          </geometry>
        </visual>
        <visual name='base_footprint_fixed_joint_lump__pole_top_3_link_visual_20'>
          <pose>-0.0381 -0.1505 0.3022 0 -0 0</pose>
          <geometry>
            <mesh>
              <scale>1 1 1</scale>
              <uri>/home/thiago/turtlebot2/src/turtlebot/turtlebot_description/meshes/stacks/hexagons/pole_top.dae</uri>
            </mesh>
          </geometry>
        </visual>
        <sensor name='bumpers' type='contact'>
          <always_on>1</always_on>
          <update_rate>50</update_rate>
          <visualize>1</visualize>
          <contact>
            <collision>base_footprint_fixed_joint_lump__base_collision</collision>
            <topic>__default_topic__</topic>
          </contact>
          <pose>0 0 0.0102 0 -0 0</pose>
        </sensor>
        <sensor name='camera' type='depth'>
          <always_on>1</always_on>
          <update_rate>20</update_rate>
          <camera>
            <horizontal_fov>1.0472</horizontal_fov>
            <image>
              <format>B8G8R8</format>
              <width>640</width>
              <height>480</height>
            </image>
            <clip>
              <near>0.05</near>
              <far>8</far>
            </clip>
          </camera>
          <plugin name='kinect_camera_controller' filename='libgazebo_ros_openni_kinect.so'>
            <cameraName>camera</cameraName>
            <alwaysOn>1</alwaysOn>
            <updateRate>10</updateRate>
            <imageTopicName>rgb/image_raw</imageTopicName>
            <depthImageTopicName>depth/image_raw</depthImageTopicName>
            <pointCloudTopicName>depth/points</pointCloudTopicName>
            <cameraInfoTopicName>rgb/camera_info</cameraInfoTopicName>
            <depthImageCameraInfoTopicName>depth/camera_info</depthImageCameraInfoTopicName>
            <frameName>camera_depth_optical_frame</frameName>
            <baseline>0.1</baseline>
            <distortion_k1>0.0</distortion_k1>
            <distortion_k2>0.0</distortion_k2>
            <distortion_k3>0.0</distortion_k3>
            <distortion_t1>0.0</distortion_t1>
            <distortion_t2>0.0</distortion_t2>
            <pointCloudCutoff>0.4</pointCloudCutoff>
            <robotNamespace>/</robotNamespace>
          </plugin>
          <pose>-0.087 -0.025 0.2972 0 -0 0</pose>
        </sensor>
        <sensor name='cliff_sensor_front' type='ray'>
          <always_on>1</always_on>
          <update_rate>50</update_rate>
          <visualize>1</visualize>
          <ray>
            <scan>
              <horizontal>
                <samples>50</samples>
                <resolution>1</resolution>
                <min_angle>-0.0436</min_angle>
                <max_angle>0.0436</max_angle>
              </horizontal>
              <vertical>
                <samples>1</samples>
                <min_angle>0</min_angle>
                <max_angle>0</max_angle>
              </vertical>
            </scan>
            <range>
              <min>0.01</min>
              <max>0.15</max>
              <resolution>1</resolution>
            </range>
          </ray>
          <pose>0.156 0 0.0316 3.14159 1.57079 3.14159</pose>
        </sensor>
        <sensor name='cliff_sensor_left' type='ray'>
          <always_on>1</always_on>
          <update_rate>50</update_rate>
          <visualize>1</visualize>
          <ray>
            <scan>
              <horizontal>
                <samples>50</samples>
                <resolution>1</resolution>
                <min_angle>-0.0436</min_angle>
                <max_angle>0.0436</max_angle>
              </horizontal>
              <vertical>
                <samples>1</samples>
                <min_angle>0</min_angle>
                <max_angle>0</max_angle>
              </vertical>
            </scan>
            <range>
              <min>0.01</min>
              <max>0.15</max>
              <resolution>1</resolution>
            </range>
          </ray>
          <pose>0.08734 0.13601 0.0316 3.14159 1.57079 3.14159</pose>
        </sensor>
        <sensor name='cliff_sensor_right' type='ray'>
          <always_on>1</always_on>
          <update_rate>50</update_rate>
          <visualize>1</visualize>
          <ray>
            <scan>
              <horizontal>
                <samples>50</samples>
                <resolution>1</resolution>
                <min_angle>-0.0436</min_angle>
                <max_angle>0.0436</max_angle>
              </horizontal>
              <vertical>
                <samples>1</samples>
                <min_angle>0</min_angle>
                <max_angle>0</max_angle>
              </vertical>
            </scan>
            <range>
              <min>0.01</min>
              <max>0.15</max>
              <resolution>1</resolution>
            </range>
          </ray>
          <pose>0.085 -0.13601 0.0316 3.14159 1.57079 3.14159</pose>
        </sensor>
        <sensor name='imu' type='imu'>
          <always_on>1</always_on>
          <update_rate>50</update_rate>
          <visualize>0</visualize>
          <imu>
            <noise>
              <type>gaussian</type>
              <rate>
                <mean>0.0</mean>
                <stddev>1.96e-06</stddev>
                <bias_mean>0.0</bias_mean>
                <bias_stddev>0.0</bias_stddev>
              </rate>
              <accel>
                <mean>0.0</mean>
                <stddev>1.7e-2</stddev>
                <bias_mean>0.1</bias_mean>
                <bias_stddev>0.001</bias_stddev>
              </accel>
            </noise>
          </imu>
          <pose>0.056 0.062 0.0304 0 -0 0</pose>
        </sensor>
        <self_collide>0</self_collide>
        <enable_wind>0</enable_wind>
        <kinematic>0</kinematic>
      </link>
      <joint name='wheel_left_joint' type='revolute'>
        <pose relative_to='base_footprint'>0 0.115 0.0352 -1.5708 0 0</pose>
        <parent>base_footprint</parent>
        <child>wheel_left_link</child>
        <axis>
          <xyz>0 0 1</xyz>
          <limit>
            <lower>-1e+16</lower>
            <upper>1e+16</upper>
          </limit>
          <dynamics>
            <spring_reference>0</spring_reference>
            <spring_stiffness>0</spring_stiffness>
          </dynamics>
        </axis>
      </joint>
      <link name='wheel_left_link'>
        <pose relative_to='wheel_left_joint'>0 0 0 0 -0 0</pose>
        <inertial>
          <pose>0 0 0 0 -0 0</pose>
          <mass>0.01</mass>
          <inertia>
            <ixx>0.001</ixx>
            <ixy>0</ixy>
            <ixz>0</ixz>
            <iyy>0.001</iyy>
            <iyz>0</iyz>
            <izz>0.001</izz>
          </inertia>
        </inertial>
        <collision name='wheel_left_link_collision'>
          <pose>0 0 0 0 -0 0</pose>
          <geometry>
            <cylinder>
              <length>0.0206</length>
              <radius>0.035</radius>
            </cylinder>
          </geometry>
          <surface>
            <contact>
              <ode>
                <kp>1e+06</kp>
                <kd>100</kd>
                <max_vel>1</max_vel>
                <min_depth>0.001</min_depth>
              </ode>
            </contact>
            <friction>
              <ode>
                <mu>1</mu>
                <mu2>1</mu2>
              </ode>
              <torsional>
                <ode/>
              </torsional>
            </friction>
            <bounce/>
          </surface>
          <max_contacts>10</max_contacts>
        </collision>
        <visual name='wheel_left_link_visual'>
          <pose>0 0 0 0 -0 0</pose>
          <geometry>
            <mesh>
              <scale>1 1 1</scale>
              <uri>/home/thiago/turtlebot2/src/kobuki_description/meshes/wheel.dae</uri>
            </mesh>
          </geometry>
        </visual>
        <self_collide>0</self_collide>
        <enable_wind>0</enable_wind>
        <kinematic>0</kinematic>
      </link>
      <joint name='wheel_right_joint' type='revolute'>
        <pose relative_to='base_footprint'>0 -0.115 0.0352 -1.5708 0 0</pose>
        <parent>base_footprint</parent>
        <child>wheel_right_link</child>
        <axis>
          <xyz>0 0 1</xyz>
          <limit>
            <lower>-1e+16</lower>
            <upper>1e+16</upper>
          </limit>
          <dynamics>
            <spring_reference>0</spring_reference>
            <spring_stiffness>0</spring_stiffness>
          </dynamics>
        </axis>
      </joint>
      <link name='wheel_right_link'>
        <pose relative_to='wheel_right_joint'>0 0 0 0 -0 0</pose>
        <inertial>
          <pose>0 0 0 0 -0 0</pose>
          <mass>0.01</mass>
          <inertia>
            <ixx>0.001</ixx>
            <ixy>0</ixy>
            <ixz>0</ixz>
            <iyy>0.001</iyy>
            <iyz>0</iyz>
            <izz>0.001</izz>
          </inertia>
        </inertial>
        <collision name='wheel_right_link_collision'>
          <pose>0 0 0 0 -0 0</pose>
          <geometry>
            <cylinder>
              <length>0.0206</length>
              <radius>0.035</radius>
            </cylinder>
          </geometry>
          <surface>
            <contact>
              <ode>
                <kp>1e+06</kp>
                <kd>100</kd>
                <max_vel>1</max_vel>
                <min_depth>0.001</min_depth>
              </ode>
            </contact>
            <friction>
              <ode>
                <mu>1</mu>
                <mu2>1</mu2>
              </ode>
              <torsional>
                <ode/>
              </torsional>
            </friction>
            <bounce/>
          </surface>
          <max_contacts>10</max_contacts>
        </collision>
        <visual name='wheel_right_link_visual'>
          <pose>0 0 0 0 -0 0</pose>
          <geometry>
            <mesh>
              <scale>1 1 1</scale>
              <uri>/home/thiago/turtlebot2/src/kobuki_description/meshes/wheel.dae</uri>
            </mesh>
          </geometry>
        </visual>
        <self_collide>0</self_collide>
        <enable_wind>0</enable_wind>
        <kinematic>0</kinematic>
      </link>
      <static>0</static>
      <plugin name='kobuki_controller' filename='libgazebo_ros_kobuki.so'>
        <publish_tf>1</publish_tf>
        <left_wheel_joint_name>wheel_left_joint</left_wheel_joint_name>
        <right_wheel_joint_name>wheel_right_joint</right_wheel_joint_name>
        <wheel_separation>.230</wheel_separation>
        <wheel_diameter>0.070</wheel_diameter>
        <torque>1.0</torque>
        <velocity_command_timeout>0.6</velocity_command_timeout>
        <cliff_sensor_left_name>cliff_sensor_left</cliff_sensor_left_name>
        <cliff_sensor_center_name>cliff_sensor_front</cliff_sensor_center_name>
        <cliff_sensor_right_name>cliff_sensor_right</cliff_sensor_right_name>
        <cliff_detection_threshold>0.04</cliff_detection_threshold>
        <bumper_name>bumpers</bumper_name>
        <imu_name>imu</imu_name>
        <robotNamespace>/</robotNamespace>
      </plugin>
      <pose>0 0 0 0 -0 0</pose>
    </model>
    <model name='aruco_visual_marker_3'>
      <link name='marker'>
        <pose>0 0 0 0 -0 0</pose>
        <visual name='visual'>
          <geometry>
            <box>
              <size>0.1778 0.1778 1e-05</size>
            </box>
          </geometry>
          <material>
            <script>
              <uri>model://aruco_visual_marker_3/materials/scripts</uri>
              <uri>model://aruco_visual_marker_3/materials/textures</uri>
              <name>ArucoVisualMarker3/Marker</name>
            </script>
            <ambient>1 1 1 1</ambient>
            <diffuse>1 1 1 1</diffuse>
            <specular>0 0 0 1</specular>
            <emissive>1 1 1 0</emissive>
            <shader type='vertex'>
              <normal_map>__default__</normal_map>
            </shader>
          </material>
          <pose>0 0 0 0 -0 0</pose>
          <cast_shadows>1</cast_shadows>
          <transparency>0</transparency>
        </visual>
        <collision name='collision'>
          <laser_retro>0</laser_retro>
          <max_contacts>10</max_contacts>
          <pose>0 0 0 0 -0 0</pose>
          <geometry>
            <box>
              <size>0.1778 0.1778 1e-05</size>
            </box>
          </geometry>
          <surface>
            <contact>
              <ode/>
            </contact>
            <bounce/>
            <friction>
              <torsional>
                <ode/>
              </torsional>
              <ode/>
            </friction>
          </surface>
        </collision>
        <self_collide>0</self_collide>
        <enable_wind>0</enable_wind>
        <kinematic>0</kinematic>
      </link>
      <link name='marker_pad'>
        <pose relative_to='marker'>0 0 -1e-05 0 -0 0</pose>
        <visual name='visual'>
          <geometry>
            <box>
              <size>0.1778 0.1778 1e-05</size>
            </box>
          </geometry>
          <material>
            <lighting>1</lighting>
            <script>
              <uri>file://media/materials/scripts/gazebo.material</uri>
              <name>Gazebo/White</name>
            </script>
            <ambient>0.3 0.3 0.3 1</ambient>
            <diffuse>0.7 0.7 0.7 1</diffuse>
            <specular>0.01 0.01 0.01 1</specular>
            <emissive>1 1 1 0</emissive>
            <shader type='vertex'>
              <normal_map>__default__</normal_map>
            </shader>
          </material>
          <cast_shadows>1</cast_shadows>
          <transparency>0</transparency>
        </visual>
        <collision name='collision'>
          <laser_retro>0</laser_retro>
          <max_contacts>10</max_contacts>
          <pose>0 0 0 0 -0 0</pose>
          <geometry>
            <box>
              <size>0.1778 0.1778 1e-05</size>
            </box>
          </geometry>
          <surface>
            <contact>
              <ode/>
            </contact>
            <bounce/>
            <friction>
              <torsional>
                <ode/>
              </torsional>
              <ode/>
            </friction>
          </surface>
        </collision>
        <self_collide>0</self_collide>
        <enable_wind>0</enable_wind>
        <kinematic>0</kinematic>
      </link>
      <joint name='marker_JOINT_marker_pad' type='revolute'>
        <parent>marker</parent>
        <child>marker_pad</child>
        <pose>0 0 0 0 -0 0</pose>
        <axis>
          <xyz>0 0 1</xyz>
          <limit>
            <upper>0</upper>
            <lower>0</lower>
          </limit>
          <dynamics>
            <spring_reference>0</spring_reference>
            <spring_stiffness>0</spring_stiffness>
          </dynamics>
        </axis>
      </joint>
      <static>1</static>
      <allow_auto_disable>1</allow_auto_disable>
      <pose>-1.57103 -0.329473 0 0 -0 0</pose>
    </model>
    <model name='aruco_visual_marker_0'>
      <link name='marker'>
        <pose>0 0 0 0 -0 0</pose>
        <visual name='visual'>
          <geometry>
            <box>
              <size>0.1778 0.1778 1e-05</size>
            </box>
          </geometry>
          <material>
            <script>
              <uri>model://aruco_visual_marker_0/materials/scripts</uri>
              <uri>model://aruco_visual_marker_0/materials/textures</uri>
              <name>ArucoVisualMarker0/Marker</name>
            </script>
            <ambient>1 1 1 1</ambient>
            <diffuse>1 1 1 1</diffuse>
            <specular>0 0 0 1</specular>
            <emissive>1 1 1 0</emissive>
            <shader type='vertex'>
              <normal_map>__default__</normal_map>
            </shader>
          </material>
          <pose>0 0 0 0 -0 0</pose>
          <cast_shadows>1</cast_shadows>
          <transparency>0</transparency>
        </visual>
        <collision name='collision'>
          <laser_retro>0</laser_retro>
          <max_contacts>10</max_contacts>
          <pose>0 0 0 0 -0 0</pose>
          <geometry>
            <box>
              <size>0.1778 0.1778 1e-05</size>
            </box>
          </geometry>
          <surface>
            <contact>
              <ode/>
            </contact>
            <bounce/>
            <friction>
              <torsional>
                <ode/>
              </torsional>
              <ode/>
            </friction>
          </surface>
        </collision>
        <self_collide>0</self_collide>
        <enable_wind>0</enable_wind>
        <kinematic>0</kinematic>
      </link>
      <link name='marker_pad'>
        <pose relative_to='marker'>0 0 -1e-05 0 -0 0</pose>
        <visual name='visual'>
          <geometry>
            <box>
              <size>0.1778 0.1778 1e-05</size>
            </box>
          </geometry>
          <material>
            <lighting>1</lighting>
            <script>
              <uri>file://media/materials/scripts/gazebo.material</uri>
              <name>Gazebo/White</name>
            </script>
            <ambient>0.3 0.3 0.3 1</ambient>
            <diffuse>0.7 0.7 0.7 1</diffuse>
            <specular>0.01 0.01 0.01 1</specular>
            <emissive>1 1 1 0</emissive>
            <shader type='vertex'>
              <normal_map>__default__</normal_map>
            </shader>
          </material>
          <cast_shadows>1</cast_shadows>
          <transparency>0</transparency>
        </visual>
        <collision name='collision'>
          <laser_retro>0</laser_retro>
          <max_contacts>10</max_contacts>
          <pose>0 0 0 0 -0 0</pose>
          <geometry>
            <box>
              <size>0.1778 0.1778 1e-05</size>
            </box>
          </geometry>
          <surface>
            <contact>
              <ode/>
            </contact>
            <bounce/>
            <friction>
              <torsional>
                <ode/>
              </torsional>
              <ode/>
            </friction>
          </surface>
        </collision>
        <self_collide>0</self_collide>
        <enable_wind>0</enable_wind>
        <kinematic>0</kinematic>
      </link>
      <joint name='marker_JOINT_marker_pad' type='revolute'>
        <parent>marker</parent>
        <child>marker_pad</child>
        <pose>0 0 0 0 -0 0</pose>
        <axis>
          <xyz>0 0 1</xyz>
          <limit>
            <upper>0</upper>
            <lower>0</lower>
          </limit>
          <dynamics>
            <spring_reference>0</spring_reference>
            <spring_stiffness>0</spring_stiffness>
          </dynamics>
        </axis>
      </joint>
      <static>1</static>
      <allow_auto_disable>1</allow_auto_disable>
      <pose>3.04483 0.013641 0 0 -0 0</pose>
    </model>
    <model name='aruco_visual_marker_1'>
      <link name='marker'>
        <pose>0 0 0 0 -0 0</pose>
        <visual name='visual'>
          <geometry>
            <box>
              <size>0.1778 0.1778 1e-05</size>
            </box>
          </geometry>
          <material>
            <script>
              <uri>model://aruco_visual_marker_1/materials/scripts</uri>
              <uri>model://aruco_visual_marker_1/materials/textures</uri>
              <name>ArucoVisualMarker1/Marker</name>
            </script>
            <ambient>1 1 1 1</ambient>
            <diffuse>1 1 1 1</diffuse>
            <specular>0 0 0 1</specular>
            <emissive>1 1 1 0</emissive>
            <shader type='vertex'>
              <normal_map>__default__</normal_map>
            </shader>
          </material>
          <pose>0 0 0 0 -0 0</pose>
          <cast_shadows>1</cast_shadows>
          <transparency>0</transparency>
        </visual>
        <collision name='collision'>
          <laser_retro>0</laser_retro>
          <max_contacts>10</max_contacts>
          <pose>0 0 0 0 -0 0</pose>
          <geometry>
            <box>
              <size>0.1778 0.1778 1e-05</size>
            </box>
          </geometry>
          <surface>
            <contact>
              <ode/>
            </contact>
            <bounce/>
            <friction>
              <torsional>
                <ode/>
              </torsional>
              <ode/>
            </friction>
          </surface>
        </collision>
        <self_collide>0</self_collide>
        <enable_wind>0</enable_wind>
        <kinematic>0</kinematic>
      </link>
      <link name='marker_pad'>
        <pose relative_to='marker'>0 0 -1e-05 0 -0 0</pose>
        <visual name='visual'>
          <geometry>
            <box>
              <size>0.1778 0.1778 1e-05</size>
            </box>
          </geometry>
          <material>
            <lighting>1</lighting>
            <script>
              <uri>file://media/materials/scripts/gazebo.material</uri>
              <name>Gazebo/White</name>
            </script>
            <ambient>0.3 0.3 0.3 1</ambient>
            <diffuse>0.7 0.7 0.7 1</diffuse>
            <specular>0.01 0.01 0.01 1</specular>
            <emissive>1 1 1 0</emissive>
            <shader type='vertex'>
              <normal_map>__default__</normal_map>
            </shader>
          </material>
          <cast_shadows>1</cast_shadows>
          <transparency>0</transparency>
        </visual>
        <collision name='collision'>
          <laser_retro>0</laser_retro>
          <max_contacts>10</max_contacts>
          <pose>0 0 0 0 -0 0</pose>
          <geometry>
            <box>
              <size>0.1778 0.1778 1e-05</size>
            </box>
          </geometry>
          <surface>
            <contact>
              <ode/>
            </contact>
            <bounce/>
            <friction>
              <torsional>
                <ode/>
              </torsional>
              <ode/>
            </friction>
          </surface>
        </collision>
        <self_collide>0</self_collide>
        <enable_wind>0</enable_wind>
        <kinematic>0</kinematic>
      </link>
      <joint name='marker_JOINT_marker_pad' type='revolute'>
        <parent>marker</parent>
        <child>marker_pad</child>
        <pose>0 0 0 0 -0 0</pose>
        <axis>
          <xyz>0 0 1</xyz>
          <limit>
            <upper>0</upper>
            <lower>0</lower>
          </limit>
          <dynamics>
            <spring_reference>0</spring_reference>
            <spring_stiffness>0</spring_stiffness>
          </dynamics>
        </axis>
      </joint>
      <static>1</static>
      <allow_auto_disable>1</allow_auto_disable>
      <pose>0 0 0 0 -0 0</pose>
    </model>
    <model name='aruco_visual_marker_2'>
      <link name='marker'>
        <pose>0 0 0 0 -0 0</pose>
        <visual name='visual'>
          <geometry>
            <box>
              <size>0.1778 0.1778 1e-05</size>
            </box>
          </geometry>
          <material>
            <script>
              <uri>model://aruco_visual_marker_2/materials/scripts</uri>
              <uri>model://aruco_visual_marker_2/materials/textures</uri>
              <name>ArucoVisualMarker2/Marker</name>
            </script>
            <ambient>1 1 1 1</ambient>
            <diffuse>1 1 1 1</diffuse>
            <specular>0 0 0 1</specular>
            <emissive>1 1 1 0</emissive>
            <shader type='vertex'>
              <normal_map>__default__</normal_map>
            </shader>
          </material>
          <pose>0 0 0 0 -0 0</pose>
          <cast_shadows>1</cast_shadows>
          <transparency>0</transparency>
        </visual>
        <collision name='collision'>
          <laser_retro>0</laser_retro>
          <max_contacts>10</max_contacts>
          <pose>0 0 0 0 -0 0</pose>
          <geometry>
            <box>
              <size>0.1778 0.1778 1e-05</size>
            </box>
          </geometry>
          <surface>
            <contact>
              <ode/>
            </contact>
            <bounce/>
            <friction>
              <torsional>
                <ode/>
              </torsional>
              <ode/>
            </friction>
          </surface>
        </collision>
        <self_collide>0</self_collide>
        <enable_wind>0</enable_wind>
        <kinematic>0</kinematic>
      </link>
      <link name='marker_pad'>
        <pose relative_to='marker'>0 0 -1e-05 0 -0 0</pose>
        <visual name='visual'>
          <geometry>
            <box>
              <size>0.1778 0.1778 1e-05</size>
            </box>
          </geometry>
          <material>
            <lighting>1</lighting>
            <script>
              <uri>file://media/materials/scripts/gazebo.material</uri>
              <name>Gazebo/White</name>
            </script>
            <ambient>0.3 0.3 0.3 1</ambient>
            <diffuse>0.7 0.7 0.7 1</diffuse>
            <specular>0.01 0.01 0.01 1</specular>
            <emissive>1 1 1 0</emissive>
            <shader type='vertex'>
              <normal_map>__default__</normal_map>
            </shader>
          </material>
          <cast_shadows>1</cast_shadows>
          <transparency>0</transparency>
        </visual>
        <collision name='collision'>
          <laser_retro>0</laser_retro>
          <max_contacts>10</max_contacts>
          <pose>0 0 0 0 -0 0</pose>
          <geometry>
            <box>
              <size>0.1778 0.1778 1e-05</size>
            </box>
          </geometry>
          <surface>
            <contact>
              <ode/>
            </contact>
            <bounce/>
            <friction>
              <torsional>
                <ode/>
              </torsional>
              <ode/>
            </friction>
          </surface>
        </collision>
        <self_collide>0</self_collide>
        <enable_wind>0</enable_wind>
        <kinematic>0</kinematic>
      </link>
      <joint name='marker_JOINT_marker_pad' type='revolute'>
        <parent>marker</parent>
        <child>marker_pad</child>
        <pose>0 0 0 0 -0 0</pose>
        <axis>
          <xyz>0 0 1</xyz>
          <limit>
            <upper>0</upper>
            <lower>0</lower>
          </limit>
          <dynamics>
            <spring_reference>0</spring_reference>
            <spring_stiffness>0</spring_stiffness>
          </dynamics>
        </axis>
      </joint>
      <static>1</static>
      <allow_auto_disable>1</allow_auto_disable>
      <pose>2.34626 2.82116 0 0 -0 0</pose>
    </model>
    <model name='aruco_visual_marker_4'>
      <link name='marker'>
        <pose>0 0 0 0 -0 0</pose>
        <visual name='visual'>
          <geometry>
            <box>
              <size>0.1778 0.1778 1e-05</size>
            </box>
          </geometry>
          <material>
            <script>
              <uri>model://aruco_visual_marker_4/materials/scripts</uri>
              <uri>model://aruco_visual_marker_4/materials/textures</uri>
              <name>ArucoVisualMarker4/Marker</name>
            </script>
            <ambient>1 1 1 1</ambient>
            <diffuse>1 1 1 1</diffuse>
            <specular>0 0 0 1</specular>
            <emissive>1 1 1 0</emissive>
            <shader type='vertex'>
              <normal_map>__default__</normal_map>
            </shader>
          </material>
          <pose>0 0 0 0 -0 0</pose>
          <cast_shadows>1</cast_shadows>
          <transparency>0</transparency>
        </visual>
        <collision name='collision'>
          <laser_retro>0</laser_retro>
          <max_contacts>10</max_contacts>
          <pose>0 0 0 0 -0 0</pose>
          <geometry>
            <box>
              <size>0.1778 0.1778 1e-05</size>
            </box>
          </geometry>
          <surface>
            <contact>
              <ode/>
            </contact>
            <bounce/>
            <friction>
              <torsional>
                <ode/>
              </torsional>
              <ode/>
            </friction>
          </surface>
        </collision>
        <self_collide>0</self_collide>
        <enable_wind>0</enable_wind>
        <kinematic>0</kinematic>
      </link>
      <link name='marker_pad'>
        <pose relative_to='marker'>0 0 -1e-05 0 -0 0</pose>
        <visual name='visual'>
          <geometry>
            <box>
              <size>0.1778 0.1778 1e-05</size>
            </box>
          </geometry>
          <material>
            <lighting>1</lighting>
            <script>
              <uri>file://media/materials/scripts/gazebo.material</uri>
              <name>Gazebo/White</name>
            </script>
            <ambient>0.3 0.3 0.3 1</ambient>
            <diffuse>0.7 0.7 0.7 1</diffuse>
            <specular>0.01 0.01 0.01 1</specular>
            <emissive>1 1 1 0</emissive>
            <shader type='vertex'>
              <normal_map>__default__</normal_map>
            </shader>
          </material>
          <cast_shadows>1</cast_shadows>
          <transparency>0</transparency>
        </visual>
        <collision name='collision'>
          <laser_retro>0</laser_retro>
          <max_contacts>10</max_contacts>
          <pose>0 0 0 0 -0 0</pose>
          <geometry>
            <box>
              <size>0.1778 0.1778 1e-05</size>
            </box>
          </geometry>
          <surface>
            <contact>
              <ode/>
            </contact>
            <bounce/>
            <friction>
              <torsional>
                <ode/>
              </torsional>
              <ode/>
            </friction>
          </surface>
        </collision>
        <self_collide>0</self_collide>
        <enable_wind>0</enable_wind>
        <kinematic>0</kinematic>
      </link>
      <joint name='marker_JOINT_marker_pad' type='revolute'>
        <parent>marker</parent>
        <child>marker_pad</child>
        <pose>0 0 0 0 -0 0</pose>
        <axis>
          <xyz>0 0 1</xyz>
          <limit>
            <upper>0</upper>
            <lower>0</lower>
          </limit>
          <dynamics>
            <spring_reference>0</spring_reference>
            <spring_stiffness>0</spring_stiffness>
          </dynamics>
        </axis>
      </joint>
      <static>1</static>
      <allow_auto_disable>1</allow_auto_disable>
      <pose>2.048 3.06109 0 0 -0 0</pose>
    </model>
  </world>
</sdf>
